Workbook
Name NativeTimeline_Order_Date: #N/A
Name Slicer_Loyalty_Card: #N/A
Name Slicer_Roast_type_Name: #N/A
Name Slicer_Size: #N/A

Sheet Detail1
A1: Details for Sum of Sales - Months (Order Date): Apr, Years (Order Date): 2019, Coffee Type name :
A3: Order ID | B3: Order Date | C3: Customer ID | D3: Product ID | E3: Quantity | F3: Customer Name | G3: Email | H3: Country | I3: Coffee Type | J3: Roast Type | K3: Size | L3: Unit Price | M3: Sales | N3: Coffee Type name | O3: Roast type Name
A4: NCH-55389-562 | B4: 43582 | C4: 86579-92122-OC | D4: A-L-0.2 | E4: 2 | F4: Brenn Dundredge | H4: #N/A | I4: Coffee Type | J4: Roast Type | K4: Size | L4: Unit Price | M4: #VALUE!

Sheet Detail2
A1: Details for Sum of Sales - Years (Order Date): 2019
A3: Order ID | B3: Order Date | C3: Customer ID | D3: Product ID | E3: Quantity | F3: Customer Name | G3: Email | H3: Country | I3: Coffee Type | J3: Roast Type | K3: Size | L3: Unit Price | M3: Sales | N3: Coffee Type name | O3: Roast type Name
A4: GTT-73214-334 | B4: 43485 | C4: 98636-90072-YE | D4: A-L-1 | E4: 6 | F4: Nobe Buney | G4: nbuneylx@jugem.jp | H4: United States | I4: Ara | J4: L | K4: 0.5 | L4: 7.77 | M4: 46.62 | N4: Arabica | O4: Light
A5: FWU-44971-444 | B5: 43476 | C5: 12190-25421-WM | D5: A-D-2.5 | E5: 3 | F5: Marvin Malloy | G5: mmalloyi6@seattletimes.com | H5: United States | I5: Ara | J5: D | K5: 1 | L5: 9.95 | M5: 29.85 | N5: Arabica | O5: Dark
A6: ABO-29054-365 | B6: 43484 | C6: 00256-19905-YG | D6: A-M-0.5 | E6: 6 | F6: Stanislaus Valsler | H6: Ireland | I6: Ara | J6: M | K6: 0.2 | L6: 3.375 | M6: 20.25 | N6: Arabica | O6: Medium
A7: GPW-43956-761 | B7: 43491 | C7: 09667-09231-YM | D7: E-L-0.5 | E7: 6 | F7: Bearnard Wardell | G7: bwardellqu@adobe.com | H7: United States | I7: Exc | J7: L | K7: 0.2 | L7: 4.455 | M7: 26.73 | N7: Excelsa | O7: Light
A8: TNR-84447-052 | B8: 43474 | C8: 34419-18068-AG | D8: E-D-2.5 | E8: 4 | F8: Dolores Duffie | G8: dduffiepr@time.com | H8: United States | I8: Exc | J8: D | K8: 1 | L8: 12.15 | M8: 48.6 | N8: Excelsa | O8: Dark
A9: IMP-12563-728 | B9: 43468 | C9: 68346-14810-UA | D9: E-L-0.5 | E9: 6 | F9: Spencer Wastell | H9: United States | I9: Exc | J9: L | K9: 0.2 | L9: 4.455 | M9: 26.73 | N9: Excelsa | O9: Light
A10: KFJ-46568-890 | B10: 43485 | C10: 71003-85639-HB | D10: E-L-0.5 | E10: 2 | F10: Lyell Murch | H10: United States | I10: Exc | J10: L | K10: 0.2 | L10: 4.455 | M10: 8.91 | N10: Excelsa | O10: Light
A11: CYZ-37122-164 | B11: 43471 | C11: 21798-04171-XC | D11: E-M-0.5 | E11: 2 | F11: Wilton Cottier | G11: wcottierj3@cafepress.com | H11: United States | I11: Exc | J11: M | K11: 0.2 | L11: 4.125 | M11: 8.25 | N11: Excelsa | O11: Medium
A12: CTE-31437-326 | B12: 43467 | C12: 22721-63196-UJ | D12: E-M-0.2 | E12: 4 | F12: Gladi Ducker | G12: gduckerdx@patch.com | H12: United Kingdom | I12: Exc | J12: L | K12: 2.5 | L12: 34.155 | M12: 136.62 | N12: Excelsa | O12: Light
A13: EQE-31648-909 | B13: 43483 | C13: 19821-05175-WZ | D13: E-D-0.5 | E13: 5 | F13: Angie Rizzetti | G13: arizzetti55@naver.com | H13: United States | I13: Exc | J13: D | K13: 0.2 | L13: 3.645 | M13: 18.225 | N13: Excelsa | O13: Dark
A14: LDK-71031-121 | B14: 43475 | C14: 84761-40784-SV | D14: L-L-2.5 | E14: 1 | F14: Andie Rudram | G14: arudramka@prnewswire.com | H14: United States | I14: Lib | J14: L | K14: 1 | L14: 15.85 | M14: 15.85 | N14: Liberica | O14: Light
A15: AYY-83051-752 | B15: 43487 | C15: 46431-09298-OU | D15: L-L-1 | E15: 6 | F15: Carolee Winchcombe | G15: cwinchcombeho@jiathis.com | H15: United States | I15: Lib | J15: L | K15: 0.5 | L15: 9.51 | M15: 57.06 | N15: Liberica | O15: Light
A16: CTE-31437-326 | B16: 43467 | C16: 22721-63196-UJ | D16: L-D-1 | E16: 4 | F16: Gladi Ducker | G16: gduckerdx@patch.com | H16: #N/A | I16: Lib | J16: D | K16: 0.5 | L16: 7.77 | M16: 31.08 | N16: Liberica | O16: Dark
A17: VJF-46305-323 | B17: 43483 | C17: 68555-89840-GZ | D17: L-D-0.5 | E17: 2 | F17: Morgen Seson | G17: msesonck@census.gov | H17: United States | I17: Lib | J17: D | K17: 0.2 | L17: 3.885 | M17: 7.77 | N17: Liberica | O17: Dark
A18: EZT-46571-659 | B18: 43467 | C18: 03396-68805-ZC | D18: R-M-0.5 | E18: 3 | F18: Guthrey Petracci | G18: gpetracci8@livejournal.com | H18: United States | I18: Rob | J18: M | K18: 0.2 | L18: 2.985 | M18: 8.955 | N18: Robusta | O18: Medium
A19: TID-21626-411 | B19: 43468 | C19: 19383-33606-PW | D19: R-L-0.5 | E19: 3 | F19: Suzanna Bollam | G19: sbollamlf@list-manage.com | H19: United States | I19: Rob | J19: L | K19: 0.2 | L19: 3.585 | M19: 10.755 | N19: Robusta | O19: Light
A20: OUQ-73954-002 | B20: 43471 | C20: 66308-13503-KD | D20: R-M-0.2 | E20: 4 | F20: Krissie Hammett | G20: khammettgm@dmoz.org | H20: United States | I20: Rob | J20: L | K20: 2.5 | L20: 27.485 | M20: 109.94 | N20: Robusta | O20: Light
A21: KAR-24978-271 | B21: 43475 | C21: 23187-65750-HZ | D21: R-M-1 | E21: 6 | F21: Starr Arpin | G21: sarpinep@moonfruit.com | H21: United States | I21: Rob | J21: M | K21: 0.5 | L21: 5.97 | M21: 35.82 | N21: Robusta | O21: Medium
A22: CTE-31437-326 | B22: 43467 | C22: 22721-63196-UJ | D22: L-L-0.2 | E22: 3 | F22: Gladi Ducker | G22: gduckerdx@patch.com | H22: #N/A | I22: Rob | J22: D | K22: 2.5 | L22: 20.585 | M22: 61.755 | N22: Robusta | O22: Dark
A23: CTE-31437-326 | B23: 43467 | C23: 22721-63196-UJ | D23: R-M-0.2 | E23: 4 | F23: Gladi Ducker | G23: gduckerdx@patch.com | H23: United Kingdom | I23: Rob | J23: L | K23: 2.5 | L23: 27.485 | M23: 109.94 | N23: Robusta | O23: Light
A24: EVP-43500-491 | B24: 43516 | C24: 49231-44455-IC | D24: A-M-0.5 | E24: 4 | F24: Selene Shales | G24: sshalesq@umich.edu | H24: United States | I24: Ara | J24: M | K24: 0.2 | L24: 3.375 | M24: 13.5 | N24: Arabica | O24: Medium
A25: RYZ-14633-602 | B25: 43516 | C25: 14158-30713-OB | D25: A-D-1 | E25: 4 | F25: Mozelle Calcutt | G25: mcalcuttt@baidu.com | H25: Ireland | I25: Ara | J25: D | K25: 0.5 | L25: 5.97 | M25: 23.88 | N25: Arabica | O25: Dark
A26: ONW-00560-570 | B26: 43521 | C26: 32900-82606-BO | D26: A-M-1 | E26: 2 | F26: Claudie Weond | G26: cweondo8@theglobeandmail.com | H26: United States | I26: Ara | J26: M | K26: 0.5 | L26: 6.75 | M26: 13.5 | N26: Arabica | O26: Medium
A27: OLF-77983-457 | B27: 43512 | C27: 51901-35210-UI | D27: A-L-2.5 | E27: 2 | F27: Gabriel Starcks | G27: gstarcksgi@abc.net.au | H27: United States | I27: Ara | J27: L | K27: 1 | L27: 12.95 | M27: 25.9 | N27: Arabica | O27: Light
A28: EAY-89850-211 | B28: 43515 | C28: 43155-71724-XP | D28: A-D-0.2 | E28: 2 | F28: Herbie Peppard | H28: United States | I28: Ara | J28: M | K28: 2.5 | L28: 25.875 | M28: 51.75 | N28: Arabica | O28: Medium
A29: XEE-37895-169 | B29: 43516 | C29: 14888-85625-TM | D29: A-L-2.5 | E29: 3 | F29: Perry Lyfield | G29: plyfielde3@baidu.com | H29: United States | I29: Ara | J29: L | K29: 1 | L29: 12.95 | M29: 38.85 | N29: Arabica | O29: Light
A30: LTD-71429-845 | B30: 43520 | C30: 03157-23165-UB | D30: A-L-0.5 | E30: 1 | F30: Flory Crumpe | G30: fcrumpe7u@ftc.gov | H30: United Kingdom | I30: Ara | J30: L | K30: 0.2 | L30: 3.885 | M30: 3.885 | N30: Arabica | O30: Light
A31: AOL-13866-711 | B31: 43510 | C31: 83490-88357-LJ | D31: E-M-1 | E31: 4 | F31: Eustace Stenton | G31: estentonms@google.it | H31: United States | I31: Exc | J31: M | K31: 0.5 | L31: 8.25 | M31: 33 | N31: Excelsa | O31: Medium
A32: BPG-68988-842 | B32: 43517 | C32: 53631-24432-SY | D32: E-M-0.5 | E32: 5 | F32: Irvine Phillpot | G32: iphillpoten@buzzfeed.com | H32: United Kingdom | I32: Exc | J32: M | K32: 0.2 | L32: 4.125 | M32: 20.625 | N32: Excelsa | O32: Medium
A33: GZS-50547-887 | B33: 43501 | C33: 61600-55136-UM | D33: E-D-1 | E33: 2 | F33: Corinna Catcheside | G33: ccatchesideaa@macromedia.com | H33: United States | I33: Exc | J33: D | K33: 0.5 | L33: 7.29 | M33: 14.58 | N33: Excelsa | O33: Dark
A34: OJU-34452-896 | B34: 43500 | C34: 60799-92593-CX | D34: E-L-0.5 | E34: 1 | F34: Abba Pummell | H34: United States | I34: Exc | J34: L | K34: 0.2 | L34: 4.455 | M34: 4.455 | N34: Excelsa | O34: Light
A35: CZD-56716-840 | B35: 43524 | C35: 15456-29250-RU | D35: L-D-2.5 | E35: 4 | F35: Jaimie Hatz | H35: United States | I35: Lib | J35: D | K35: 1 | L35: 12.95 | M35: 51.8 | N35: Liberica | O35: Dark
A36: TRZ-94735-865 | B36: 43501 | C36: 54462-58311-YF | D36: L-M-0.5 | E36: 4 | F36: Teddi Quadri | G36: tquadrikr@opensource.org | H36: Ireland | I36: Lib | J36: M | K36: 0.2 | L36: 4.365 | M36: 17.46 | N36: Liberica | O36: Medium
A37: CZG-01299-952 | B37: 43508 | C37: 09540-70637-EV | D37: L-D-1 | E37: 2 | F37: Jarret Toye | G37: jtoyekg@pinterest.com | H37: Ireland | I37: Lib | J37: D | K37: 0.5 | L37: 7.77 | M37: 15.54 | N37: Liberica | O37: Dark
A38: QLC-52637-305 | B38: 43506 | C38: 34317-87258-HQ | D38: L-D-2.5 | E38: 4 | F38: Doralin Baison | H38: Ireland | I38: Lib | J38: D | K38: 1 | L38: 12.95 | M38: 51.8 | N38: Liberica | O38: Dark
A39: JUO-34131-517 | B39: 43509 | C39: 07972-83748-JI | D39: L-D-1 | E39: 6 | F39: Rivy Farington | H39: United States | I39: Lib | J39: D | K39: 0.5 | L39: 7.77 | M39: 46.62 | N39: Liberica | O39: Dark
A40: HPD-65272-772 | B40: 43521 | C40: 57504-13456-UO | D40: L-M-2.5 | E40: 1 | F40: Parsifal Metrick | G40: pmetrick7r@rakuten.co.jp | H40: United States | I40: Lib | J40: M | K40: 1 | L40: 14.55 | M40: 14.55 | N40: Liberica | O40: Medium
A41: ZYQ-15797-695 | B41: 43521 | C41: 79436-73011-MM | D41: R-D-0.5 | E41: 5 | F41: Pammi Endacott | H41: United Kingdom | I41: Rob | J41: D | K41: 0.2 | L41: 2.685 | M41: 13.425 | N41: Robusta | O41: Dark
...

Sheet Detail3
A1: Details for Sum of Sales - Months (Order Date): Jul, Years (Order Date): 2019
A3: Order ID | B3: Order Date | C3: Customer ID | D3: Product ID | E3: Quantity | F3: Customer Name | G3: Email | H3: Country | I3: Coffee Type | J3: Roast Type | K3: Size | L3: Unit Price | M3: Sales | N3: Coffee Type name | O3: Roast type Name
A4: GPZ-36017-366 | B4: 43647 | C4: 65732-22589-OW | D4: A-D-2.5 | E4: 5 | F4: Kippie Marrison | G4: kmarrisonoq@dropbox.com | H4: United States | I4: Ara | J4: D | K4: 2.5 | L4: 22.885 | M4: 114.425 | N4: Arabica | O4: Dark
A5: MIU-01481-194 | B5: 43667 | C5: 08439-55669-AI | D5: A-L-0.5 | E5: 2 | F5: Rafferty Pursglove | G5: rpursglovel9@biblegateway.com | H5: United States | I5: Ara | J5: L | K5: 0.5 | L5: 7.77 | M5: 15.54 | N5: Arabica | O5: Light
A6: CQW-37388-302 | B6: 43649 | C6: 97741-98924-KT | D6: A-D-2.5 | E6: 3 | F6: Willabella Harvison | G6: wharvisonjx@gizmodo.com | H6: United States | I6: Ara | J6: D | K6: 2.5 | L6: 22.885 | M6: 68.655 | N6: Arabica | O6: Dark
A7: TBB-29780-459 | B7: 43661 | C7: 61437-83623-PZ | D7: A-L-0.5 | E7: 1 | F7: Vivyan Dunning | G7: vdunningji@independent.co.uk | H7: United States | I7: Ara | J7: L | K7: 0.5 | L7: 7.77 | M7: 7.77 | N7: Arabica | O7: Light
A8: LCB-02099-995 | B8: 43677 | C8: 06757-96251-UH | D8: A-D-0.2 | E8: 6 | F8: Gran Sibray | G8: gsibrayb2@wsj.com | H8: United States | I8: Ara | J8: D | K8: 0.2 | L8: 2.985 | M8: 17.91 | N8: Arabica | O8: Dark
A9: UJQ-54441-340 | B9: 43676 | C9: 26822-19510-SD | D9: A-L-0.2 | E9: 5 | F9: Gabie Tweed | G9: gtweed8v@yolasite.com | H9: United States | I9: Ara | J9: L | K9: 0.2 | L9: 3.885 | M9: 19.425 | N9: Arabica | O9: Light
A10: XXJ-47000-307 | B10: 43664 | C10: 31582-23562-FM | D10: A-D-0.2 | E10: 4 | F10: Jeffrey Dufaire | G10: jdufaire2d@fc2.com | H10: United States | I10: Ara | J10: D | K10: 0.2 | L10: 2.985 | M10: 11.94 | N10: Arabica | O10: Dark
A11: XXJ-47000-307 | B11: 43664 | C11: 31582-23562-FM | D11: A-L-2.5 | E11: 3 | F11: Jeffrey Dufaire | G11: jdufaire2d@fc2.com | H11: United States | I11: Ara | J11: L | K11: 2.5 | L11: 29.785 | M11: 89.355 | N11: Arabica | O11: Light
A12: GVG-59542-307 | B12: 43648 | C12: 26314-66792-VP | D12: E-M-1 | E12: 2 | F12: Bran Sterke | G12: bsterkekw@biblegateway.com | H12: United States | I12: Exc | J12: M | K12: 1 | L12: 13.75 | M12: 27.5 | N12: Excelsa | O12: Medium
A13: UVF-59322-459 | B13: 43671 | C13: 53971-49906-PZ | D13: E-L-2.5 | E13: 6 | F13: Daniel Heinonen | G13: dheinonengd@printfriendly.com | H13: United States | I13: Exc | J13: L | K13: 2.5 | L13: 34.155 | M13: 204.93 | N13: Excelsa | O13: Light
A14: OQS-46321-904 | B14: 43666 | C14: 19597-91185-CM | D14: E-M-1 | E14: 1 | F14: Diena Peetermann | H14: United States | I14: Exc | J14: M | K14: 1 | L14: 13.75 | M14: 13.75 | N14: Excelsa | O14: Medium
A15: UJQ-54441-340 | B15: 43676 | C15: 26822-19510-SD | D15: E-M-0.2 | E15: 2 | F15: Gabie Tweed | G15: gtweed8v@yolasite.com | H15: United States | I15: Exc | J15: M | K15: 0.2 | L15: 4.125 | M15: 8.25 | N15: Excelsa | O15: Medium
A16: OGY-19377-175 | B16: 43655 | C16: 49084-44492-OJ | D16: E-D-0.5 | E16: 1 | F16: Barney Chisnell | H16: Ireland | I16: Exc | J16: D | K16: 0.5 | L16: 7.29 | M16: 7.29 | N16: Excelsa | O16: Dark
A17: CYV-13426-645 | B17: 43652 | C17: 88593-59934-VU | D17: E-D-1 | E17: 1 | F17: Evelina Dacca | G17: edacca3l@google.pl | H17: United States | I17: Exc | J17: D | K17: 1 | L17: 12.15 | M17: 12.15 | N17: Excelsa | O17: Dark
A18: DTB-71371-705 | B18: 43649 | C18: 48544-90737-AZ | D18: L-D-1 | E18: 1 | F18: Chiarra Shalders | G18: cshaldersqx@cisco.com | H18: United States | I18: Lib | J18: D | K18: 1 | L18: 12.95 | M18: 12.95 | N18: Liberica | O18: Dark
A19: VSQ-07182-513 | B19: 43669 | C19: 18366-65239-WF | D19: L-L-0.2 | E19: 6 | F19: Brendan Grece | G19: bgrecefm@naver.com | H19: United Kingdom | I19: Lib | J19: L | K19: 0.2 | L19: 4.755 | M19: 28.53 | N19: Liberica | O19: Light
A20: LRK-97117-150 | B20: 43654 | C20: 33000-22405-LO | D20: L-L-1 | E20: 6 | F20: Sean Lorenzetti | G20: slorenzettidl@is.gd | H20: United States | I20: Lib | J20: L | K20: 1 | L20: 15.85 | M20: 95.1 | N20: Liberica | O20: Light
A21: ZQI-47236-301 | B21: 43671 | C21: 23446-47798-ID | D21: L-L-0.5 | E21: 5 | F21: Carmelita Thowes | G21: cthowescp@craigslist.org | H21: United States | I21: Lib | J21: L | K21: 0.5 | L21: 9.51 | M21: 47.55 | N21: Liberica | O21: Light
A22: HST-96923-073 | B22: 43664 | C22: 54722-76431-EX | D22: R-D-2.5 | E22: 6 | F22: Helli Petroulis | G22: hpetroulisol@state.tx.us | H22: Ireland | I22: Rob | J22: D | K22: 2.5 | L22: 20.585 | M22: 123.51 | N22: Robusta | O22: Dark
A23: MIU-01481-194 | B23: 43667 | C23: 08439-55669-AI | D23: R-M-1 | E23: 6 | F23: Rafferty Pursglove | G23: rpursglovel9@biblegateway.com | H23: United States | I23: Rob | J23: M | K23: 1 | L23: 9.95 | M23: 59.7 | N23: Robusta | O23: Medium
A24: JQT-14347-517 | B24: 43672 | C24: 11621-09964-ID | D24: R-D-1 | E24: 1 | F24: Lorelei Nardoni | G24: lnardonil2@hao123.com | H24: United States | I24: Rob | J24: D | K24: 1 | L24: 8.95 | M24: 8.95 | N24: Robusta | O24: Dark
A25: AXN-57779-891 | B25: 43660 | C25: 09668-23340-IC | D25: R-M-0.2 | E25: 3 | F25: Donavon Fowle | G25: dfowlegr@epa.gov | H25: United States | I25: Rob | J25: M | K25: 0.2 | L25: 2.985 | M25: 8.955 | N25: Robusta | O25: Medium

Sheet Dashboard
AB12: ;

Sheet TotalSales
A3: Sum of Sales | C3: Coffee Type name
A4: Years (Order Date) | B4: Months (Order Date) | C4: Arabica | D4: Excelsa | E4: Liberica | F4: Robusta | G4: Grand Total
A5: 2019 | B5: Jan | C5: 186.855 | D5: 305.97 | E5: 213.16 | F5: 123 | G5: 828.985
B6: Feb | C6: 251.965 | D6: 129.46 | E6: 434.04 | F6: 171.94 | G6: 987.405
B7: Mar | C7: 224.945 | D7: 349.12 | E7: 321.04 | F7: 126.035 | G7: 1021.14
B8: Apr | C8: 307.12 | D8: 681.075 | E8: 533.705 | F8: 158.85 | G8: 1680.75
B9: May | C9: 53.665 | D9: 83.025 | E9: 193.835 | F9: 68.04 | G9: 398.565
B10: Jun | C10: 163.02 | D10: 678.36 | E10: 171.045 | F10: 372.255 | G10: 1384.68
B11: Jul | C11: 345.02 | D11: 273.87 | E11: 184.13 | F11: 201.115 | G11: 1004.135
B12: Aug | C12: 334.89 | D12: 70.95 | E12: 134.23 | F12: 166.275 | G12: 706.345
B13: Sep | C13: 178.71 | D13: 166.1 | E13: 439.31 | F13: 492.9 | G13: 1277.02
B14: Oct | C14: 301.985 | D14: 153.765 | E14: 215.555 | F14: 213.665 | G14: 884.97
B15: Nov | C15: 312.835 | D15: 63.25 | E15: 350.895 | F15: 96.405 | G15: 823.385
B16: Dec | C16: 265.62 | D16: 526.515 | E16: 187.06 | F16: 210.59 | G16: 1189.785
A17: 2019 Total | C17: 2926.63 | D17: 3481.46 | E17: 3378.005 | F17: 2401.07 | G17: 12187.165
A18: 2020 | B18: Jan | C18: 47.25 | D18: 65.805 | E18: 274.675 | F18: 179.22 | G18: 566.95
B19: Feb | C19: 745.45 | D19: 428.885 | E19: 194.175 | F19: 429.83 | G19: 1798.34
B20: Mar | C20: 130.47 | D20: 271.485 | E20: 281.205 | F20: 231.63 | G20: 914.79
B21: Apr | C21: 27 | D21: 347.26 | E21: 147.51 | F21: 240.04 | G21: 761.81
B22: May | C22: 255.115 | D22: 541.73 | E22: 83.43 | F22: 59.08 | G22: 939.355
B23: Jun | C23: 584.79 | D23: 357.43 | E23: 355.34 | F23: 140.88 | G23: 1438.44
B24: Jul | C24: 430.62 | D24: 227.425 | E24: 236.315 | F24: 414.585 | G24: 1308.945
B25: Aug | C25: 22.5 | D25: 77.72 | E25: 60.5 | F25: 139.68 | G25: 300.4
B26: Sep | C26: 126.15 | D26: 195.11 | E26: 89.13 | F26: 302.66 | G26: 713.05
B27: Oct | C27: 376.03 | D27: 523.24 | E27: 440.965 | F27: 174.47 | G27: 1514.705
B28: Nov | C28: 515.18 | D28: 142.56 | E28: 347.04 | F28: 104.085 | G28: 1108.865
B29: Dec | C29: 95.86 | D29: 484.76 | E29: 94.17 | F29: 77.105 | G29: 751.895
A30: 2020 Total | C30: 3356.415 | D30: 3663.41 | E30: 2604.455 | F30: 2493.265 | G30: 12117.545
A31: 2021 | B31: Jan | C31: 258.345 | D31: 139.625 | E31: 279.52 | F31: 160.195 | G31: 837.685
B32: Feb | C32: 342.2 | D32: 284.25 | E32: 251.83 | F32: 80.55 | G32: 958.83
B33: Mar | C33: 418.305 | D33: 468.125 | E33: 405.055 | F33: 253.155 | G33: 1544.64
B34: Apr | C34: 102.33 | D34: 242.14 | E34: 554.875 | F34: 106.24 | G34: 1005.585
B35: May | C35: 234.72 | D35: 133.08 | E35: 267.2 | F35: 272.69 | G35: 907.69
B36: Jun | C36: 430.39 | D36: 136.205 | E36: 209.6 | F36: 88.335 | G36: 864.53
B37: Jul | C37: 109.005 | D37: 393.575 | E37: 61.035 | F37: 199.49 | G37: 763.105
B38: Aug | C38: 287.525 | D38: 288.67 | E38: 125.58 | F38: 374.135 | G38: 1075.91
B39: Sep | C39: 840.93 | D39: 409.875 | E39: 171.33 | F39: 221.44 | G39: 1643.575
B40: Oct | C40: 299.07 | D40: 260.325 | E40: 584.64 | F40: 256.365 | G40: 1400.4
B41: Nov | C41: 323.325 | D41: 565.57 | E41: 537.81 | F41: 189.475 | G41: 1616.18
B42: Dec | C42: 399.485 | D42: 148.2 | E42: 388.22 | F42: 212.075 | G42: 1147.98
...

Sheet CountryBar Chart
A3: Country | B3: Sum of Sales
A4: United Kingdom | B4: 2798.505
A5: Ireland | B5: 6696.865
A6: United States | B6: 35638.885
A7: Grand Total | B7: 45134.255

Sheet Top5Customers
A3: Customer Name | B3: Sum of Sales
A4: Don Flintiff | B4: 278.01
A5: Nealson Cuttler | B5: 281.675
A6: Terri Farra | B6: 289.11
A7: Brenn Dundredge | B7: 307.045
A8: Allis Wilmore | B8: 317.07
A9: Grand Total | B9: 1472.91

Sheet orders
A1: Order ID | B1: Order Date | C1: Customer ID | D1: Product ID | E1: Quantity | F1: Customer Name | G1: Email | H1: Country | I1: Coffee Type | J1: Roast Type | K1: Size | L1: Unit Price | M1: Sales | N1: Coffee Type name | O1: Roast type Name | P1: Loyalty Card
A2: QEV-37451-860 | B2: 43713 | C2: 17670-51384-MA | D2: R-M-1 | E2: 2 | F2: =_xlfn.XLOOKUP(orders!C2,customers!$A$1:$A$1001,customers!$B$1:$B$1001,,0) -> Aloisia Allner | G2: =IF(_xlfn.XLOOKUP(orders!C2,customers!$A$1:$A$1001,customers!$C$1:$C$1001,,0)=0,"",_xlfn.XLOOKUP(orders!C2,customers!$A$1:$A$1001,customers!$C$1:$C$1001,,0)) -> aallner0@lulu.com | H2: =_xlfn.XLOOKUP(C2,customers!$A$1:$A$1001,customers!$G$1:$G$1001,,0) -> United States | I2: =INDEX(products!$A$1:$G$49,MATCH(orders!$D2,products!$A$1:$A$49,0),MATCH(orders!I$1,products!$A$1:$G$1,0)) -> Rob | J2: =INDEX(products!$A$1:$G$49,MATCH(orders!$D2,products!$A$1:$A$49,0),MATCH(orders!J$1,products!$A$1:$G$1,0)) -> M | K2: =INDEX(products!$A$1:$G$49,MATCH(orders!$D2,products!$A$1:$A$49,0),MATCH(orders!K$1,products!$A$1:$G$1,0)) -> 1 | L2: =INDEX(products!$A$1:$G$49,MATCH(orders!$D2,products!$A$1:$A$49,0),MATCH(orders!L$1,products!$A$1:$G$1,0)) -> 9.95 | M2: =L2*E2 -> 19.9 | N2: =IF(I2="Rob","Robusta",IF(I2="Exc","Excelsa",IF(I2="Ara","Arabica",IF(I2="Lib","Liberica","")))) -> Robusta | O2: =IF(J2="M","Medium",IF(J2="L","Light",IF(J2="D","Dark",""))) -> Medium | P2: =_xlfn.XLOOKUP(Orders[[#This Row],[Customer ID]],customers!$A$1:$A$1001,customers!$I$1:$I$1001,,0) -> Yes
A3: QEV-37451-860 | B3: 43713 | C3: 17670-51384-MA | D3: E-M-0.5 | E3: 5 | F3: =_xlfn.XLOOKUP(orders!C3,customers!$A$1:$A$1001,customers!$B$1:$B$1001,,0) -> Aloisia Allner | G3: =IF(_xlfn.XLOOKUP(orders!C3,customers!$A$1:$A$1001,customers!$C$1:$C$1001,,0)=0,"",_xlfn.XLOOKUP(orders!C3,customers!$A$1:$A$1001,customers!$C$1:$C$1001,,0)) -> aallner0@lulu.com | H3: =_xlfn.XLOOKUP(C3,customers!$A$1:$A$1001,customers!$G$1:$G$1001,,0) -> United States | I3: =INDEX(products!$A$1:$G$49,MATCH(orders!$D3,products!$A$1:$A$49,0),MATCH(orders!I$1,products!$A$1:$G$1,0)) -> Exc | J3: =INDEX(products!$A$1:$G$49,MATCH(orders!$D3,products!$A$1:$A$49,0),MATCH(orders!J$1,products!$A$1:$G$1,0)) -> M | K3: =INDEX(products!$A$1:$G$49,MATCH(orders!$D3,products!$A$1:$A$49,0),MATCH(orders!K$1,products!$A$1:$G$1,0)) -> 0.5 | L3: =INDEX(products!$A$1:$G$49,MATCH(orders!$D3,products!$A$1:$A$49,0),MATCH(orders!L$1,products!$A$1:$G$1,0)) -> 8.25 | M3: =L3*E3 -> 41.25 | N3: =IF(I3="Rob","Robusta",IF(I3="Exc","Excelsa",IF(I3="Ara","Arabica",IF(I3="Lib","Liberica","")))) -> Excelsa | O3: =IF(J3="M","Medium",IF(J3="L","Light",IF(J3="D","Dark",""))) -> Medium | P3: Yes
A4: FAA-43335-268 | B4: 44364 | C4: 21125-22134-PX | D4: A-L-1 | E4: 1 | F4: =_xlfn.XLOOKUP(orders!C4,customers!$A$1:$A$1001,customers!$B$1:$B$1001,,0) -> Jami Redholes | G4: =IF(_xlfn.XLOOKUP(orders!C4,customers!$A$1:$A$1001,customers!$C$1:$C$1001,,0)=0,"",_xlfn.XLOOKUP(orders!C4,customers!$A$1:$A$1001,customers!$C$1:$C$1001,,0)) -> jredholes2@tmall.com | H4: =_xlfn.XLOOKUP(C4,customers!$A$1:$A$1001,customers!$G$1:$G$1001,,0) -> United States | I4: =INDEX(products!$A$1:$G$49,MATCH(orders!$D4,products!$A$1:$A$49,0),MATCH(orders!I$1,products!$A$1:$G$1,0)) -> Ara | J4: =INDEX(products!$A$1:$G$49,MATCH(orders!$D4,products!$A$1:$A$49,0),MATCH(orders!J$1,products!$A$1:$G$1,0)) -> L | K4: =INDEX(products!$A$1:$G$49,MATCH(orders!$D4,products!$A$1:$A$49,0),MATCH(orders!K$1,products!$A$1:$G$1,0)) -> 1 | L4: =INDEX(products!$A$1:$G$49,MATCH(orders!$D4,products!$A$1:$A$49,0),MATCH(orders!L$1,products!$A$1:$G$1,0)) -> 12.95 | M4: =L4*E4 -> 12.95 | N4: =IF(I4="Rob","Robusta",IF(I4="Exc","Excelsa",IF(I4="Ara","Arabica",IF(I4="Lib","Liberica","")))) -> Arabica | O4: =IF(J4="M","Medium",IF(J4="L","Light",IF(J4="D","Dark",""))) -> Light | P4: =_xlfn.XLOOKUP(Orders[[#This Row],[Customer ID]],customers!$A$1:$A$1001,customers!$I$1:$I$1001,,0) -> Yes
A5: KAC-83089-793 | B5: 44392 | C5: 23806-46781-OU | D5: E-M-1 | E5: 2 | F5: =_xlfn.XLOOKUP(orders!C5,customers!$A$1:$A$1001,customers!$B$1:$B$1001,,0) -> Christoffer O' Shea | G5: =IF(_xlfn.XLOOKUP(orders!C5,customers!$A$1:$A$1001,customers!$C$1:$C$1001,,0)=0,"",_xlfn.XLOOKUP(orders!C5,customers!$A$1:$A$1001,customers!$C$1:$C$1001,,0)) | H5: =_xlfn.XLOOKUP(C5,customers!$A$1:$A$1001,customers!$G$1:$G$1001,,0) -> Ireland | I5: =INDEX(products!$A$1:$G$49,MATCH(orders!$D5,products!$A$1:$A$49,0),MATCH(orders!I$1,products!$A$1:$G$1,0)) -> Exc | J5: =INDEX(products!$A$1:$G$49,MATCH(orders!$D5,products!$A$1:$A$49,0),MATCH(orders!J$1,products!$A$1:$G$1,0)) -> M | K5: =INDEX(products!$A$1:$G$49,MATCH(orders!$D5,products!$A$1:$A$49,0),MATCH(orders!K$1,products!$A$1:$G$1,0)) -> 1 | L5: =INDEX(products!$A$1:$G$49,MATCH(orders!$D5,products!$A$1:$A$49,0),MATCH(orders!L$1,products!$A$1:$G$1,0)) -> 13.75 | M5: =L5*E5 -> 27.5 | N5: =IF(I5="Rob","Robusta",IF(I5="Exc","Excelsa",IF(I5="Ara","Arabica",IF(I5="Lib","Liberica","")))) -> Excelsa | O5: =IF(J5="M","Medium",IF(J5="L","Light",IF(J5="D","Dark",""))) -> Medium | P5: =_xlfn.XLOOKUP(Orders[[#This Row],[Customer ID]],customers!$A$1:$A$1001,customers!$I$1:$I$1001,,0) -> No
A6: KAC-83089-793 | B6: 44392 | C6: 23806-46781-OU | D6: R-L-2.5 | E6: 2 | F6: =_xlfn.XLOOKUP(orders!C6,customers!$A$1:$A$1001,customers!$B$1:$B$1001,,0) -> Christoffer O' Shea | G6: =IF(_xlfn.XLOOKUP(orders!C6,customers!$A$1:$A$1001,customers!$C$1:$C$1001,,0)=0,"",_xlfn.XLOOKUP(orders!C6,customers!$A$1:$A$1001,customers!$C$1:$C$1001,,0)) | H6: =_xlfn.XLOOKUP(C6,customers!$A$1:$A$1001,customers!$G$1:$G$1001,,0) -> Ireland | I6: =INDEX(products!$A$1:$G$49,MATCH(orders!$D6,products!$A$1:$A$49,0),MATCH(orders!I$1,products!$A$1:$G$1,0)) -> Rob | J6: =INDEX(products!$A$1:$G$49,MATCH(orders!$D6,products!$A$1:$A$49,0),MATCH(orders!J$1,products!$A$1:$G$1,0)) -> L | K6: =INDEX(products!$A$1:$G$49,MATCH(orders!$D6,products!$A$1:$A$49,0),MATCH(orders!K$1,products!$A$1:$G$1,0)) -> 2.5 | L6: =INDEX(products!$A$1:$G$49,MATCH(orders!$D6,products!$A$1:$A$49,0),MATCH(orders!L$1,products!$A$1:$G$1,0)) -> 27.485 | M6: =L6*E6 -> 54.97 | N6: =IF(I6="Rob","Robusta",IF(I6="Exc","Excelsa",IF(I6="Ara","Arabica",IF(I6="Lib","Liberica","")))) -> Robusta | O6: =IF(J6="M","Medium",IF(J6="L","Light",IF(J6="D","Dark",""))) -> Light | P6: =_xlfn.XLOOKUP(Orders[[#This Row],[Customer ID]],customers!$A$1:$A$1001,customers!$I$1:$I$1001,,0) -> No
A7: CVP-18956-553 | B7: 44412 | C7: 86561-91660-RB | D7: L-D-1 | E7: 3 | F7: =_xlfn.XLOOKUP(orders!C7,customers!$A$1:$A$1001,customers!$B$1:$B$1001,,0) -> Beryle Cottier | G7: =IF(_xlfn.XLOOKUP(orders!C7,customers!$A$1:$A$1001,customers!$C$1:$C$1001,,0)=0,"",_xlfn.XLOOKUP(orders!C7,customers!$A$1:$A$1001,customers!$C$1:$C$1001,,0)) | H7: =_xlfn.XLOOKUP(C7,customers!$A$1:$A$1001,customers!$G$1:$G$1001,,0) -> United States | I7: =INDEX(products!$A$1:$G$49,MATCH(orders!$D7,products!$A$1:$A$49,0),MATCH(orders!I$1,products!$A$1:$G$1,0)) -> Lib | J7: =INDEX(products!$A$1:$G$49,MATCH(orders!$D7,products!$A$1:$A$49,0),MATCH(orders!J$1,products!$A$1:$G$1,0)) -> D | K7: =INDEX(products!$A$1:$G$49,MATCH(orders!$D7,products!$A$1:$A$49,0),MATCH(orders!K$1,products!$A$1:$G$1,0)) -> 1 | L7: =INDEX(products!$A$1:$G$49,MATCH(orders!$D7,products!$A$1:$A$49,0),MATCH(orders!L$1,products!$A$1:$G$1,0)) -> 12.95 | M7: =L7*E7 -> 38.85 | N7: =IF(I7="Rob","Robusta",IF(I7="Exc","Excelsa",IF(I7="Ara","Arabica",IF(I7="Lib","Liberica","")))) -> Liberica | O7: =IF(J7="M","Medium",IF(J7="L","Light",IF(J7="D","Dark",""))) -> Dark | P7: =_xlfn.XLOOKUP(Orders[[#This Row],[Customer ID]],customers!$A$1:$A$1001,customers!$I$1:$I$1001,,0) -> No
A8: IPP-31994-879 | B8: 44582 | C8: 65223-29612-CB | D8: E-D-0.5 | E8: 3 | F8: =_xlfn.XLOOKUP(orders!C8,customers!$A$1:$A$1001,customers!$B$1:$B$1001,,0) -> Shaylynn Lobe | G8: =IF(_xlfn.XLOOKUP(orders!C8,customers!$A$1:$A$1001,customers!$C$1:$C$1001,,0)=0,"",_xlfn.XLOOKUP(orders!C8,customers!$A$1:$A$1001,customers!$C$1:$C$1001,,0)) -> slobe6@nifty.com | H8: =_xlfn.XLOOKUP(C8,customers!$A$1:$A$1001,customers!$G$1:$G$1001,,0) -> United States | I8: =INDEX(products!$A$1:$G$49,MATCH(orders!$D8,products!$A$1:$A$49,0),MATCH(orders!I$1,products!$A$1:$G$1,0)) -> Exc | J8: =INDEX(products!$A$1:$G$49,MATCH(orders!$D8,products!$A$1:$A$49,0),MATCH(orders!J$1,products!$A$1:$G$1,0)) -> D | K8: =INDEX(products!$A$1:$G$49,MATCH(orders!$D8,products!$A$1:$A$49,0),MATCH(orders!K$1,products!$A$1:$G$1,0)) -> 0.5 | L8: =INDEX(products!$A$1:$G$49,MATCH(orders!$D8,products!$A$1:$A$49,0),MATCH(orders!L$1,products!$A$1:$G$1,0)) -> 7.29 | M8: =L8*E8 -> 21.87 | N8: =IF(I8="Rob","Robusta",IF(I8="Exc","Excelsa",IF(I8="Ara","Arabica",IF(I8="Lib","Liberica","")))) -> Excelsa | O8: =IF(J8="M","Medium",IF(J8="L","Light",IF(J8="D","Dark",""))) -> Dark | P8: =_xlfn.XLOOKUP(Orders[[#This Row],[Customer ID]],customers!$A$1:$A$1001,customers!$I$1:$I$1001,,0) -> Yes
A9: SNZ-65340-705 | B9: 44701 | C9: 21134-81676-FR | D9: L-L-0.2 | E9: 1 | F9: =_xlfn.XLOOKUP(orders!C9,customers!$A$1:$A$1001,customers!$B$1:$B$1001,,0) -> Melvin Wharfe | G9: =IF(_xlfn.XLOOKUP(orders!C9,customers!$A$1:$A$1001,customers!$C$1:$C$1001,,0)=0,"",_xlfn.XLOOKUP(orders!C9,customers!$A$1:$A$1001,customers!$C$1:$C$1001,,0)) | H9: =_xlfn.XLOOKUP(C9,customers!$A$1:$A$1001,customers!$G$1:$G$1001,,0) -> Ireland | I9: =INDEX(products!$A$1:$G$49,MATCH(orders!$D9,products!$A$1:$A$49,0),MATCH(orders!I$1,products!$A$1:$G$1,0)) -> Lib | J9: =INDEX(products!$A$1:$G$49,MATCH(orders!$D9,products!$A$1:$A$49,0),MATCH(orders!J$1,products!$A$1:$G$1,0)) -> L | K9: =INDEX(products!$A$1:$G$49,MATCH(orders!$D9,products!$A$1:$A$49,0),MATCH(orders!K$1,products!$A$1:$G$1,0)) -> 0.2 | L9: =INDEX(products!$A$1:$G$49,MATCH(orders!$D9,products!$A$1:$A$49,0),MATCH(orders!L$1,products!$A$1:$G$1,0)) -> 4.755 | M9: =L9*E9 -> 4.755 | N9: =IF(I9="Rob","Robusta",IF(I9="Exc","Excelsa",IF(I9="Ara","Arabica",IF(I9="Lib","Liberica","")))) -> Liberica | O9: =IF(J9="M","Medium",IF(J9="L","Light",IF(J9="D","Dark",""))) -> Light | P9: =_xlfn.XLOOKUP(Orders[[#This Row],[Customer ID]],customers!$A$1:$A$1001,customers!$I$1:$I$1001,,0) -> Yes
A10: EZT-46571-659 | B10: 43467 | C10: 03396-68805-ZC | D10: R-M-0.5 | E10: 3 | F10: =_xlfn.XLOOKUP(orders!C10,customers!$A$1:$A$1001,customers!$B$1:$B$1001,,0) -> Guthrey Petracci | G10: =IF(_xlfn.XLOOKUP(orders!C10,customers!$A$1:$A$1001,customers!$C$1:$C$1001,,0)=0,"",_xlfn.XLOOKUP(orders!C10,customers!$A$1:$A$1001,customers!$C$1:$C$1001,,0)) -> gpetracci8@livejournal.com | H10: =_xlfn.XLOOKUP(C10,customers!$A$1:$A$1001,customers!$G$1:$G$1001,,0) -> United States | I10: =INDEX(products!$A$1:$G$49,MATCH(orders!$D10,products!$A$1:$A$49,0),MATCH(orders!I$1,products!$A$1:$G$1,0)) -> Rob | J10: =INDEX(products!$A$1:$G$49,MATCH(orders!$D10,products!$A$1:$A$49,0),MATCH(orders!J$1,products!$A$1:$G$1,0)) -> M | K10: =INDEX(products!$A$1:$G$49,MATCH(orders!$D10,products!$A$1:$A$49,0),MATCH(orders!K$1,products!$A$1:$G$1,0)) -> 0.5 | L10: =INDEX(products!$A$1:$G$49,MATCH(orders!$D10,products!$A$1:$A$49,0),MATCH(orders!L$1,products!$A$1:$G$1,0)) -> 5.97 | M10: =L10*E10 -> 17.91 | N10: =IF(I10="Rob","Robusta",IF(I10="Exc","Excelsa",IF(I10="Ara","Arabica",IF(I10="Lib","Liberica","")))) -> Robusta | O10: =IF(J10="M","Medium",IF(J10="L","Light",IF(J10="D","Dark",""))) -> Medium | P10: =_xlfn.XLOOKUP(Orders[[#This Row],[Customer ID]],customers!$A$1:$A$1001,customers!$I$1:$I$1001,,0) -> No
A11: NWQ-70061-912 | B11: 43713 | C11: 61021-27840-ZN | D11: R-M-0.5 | E11: 1 | F11: =_xlfn.XLOOKUP(orders!C11,customers!$A$1:$A$1001,customers!$B$1:$B$1001,,0) -> Rodger Raven | G11: =IF(_xlfn.XLOOKUP(orders!C11,customers!$A$1:$A$1001,customers!$C$1:$C$1001,,0)=0,"",_xlfn.XLOOKUP(orders!C11,customers!$A$1:$A$1001,customers!$C$1:$C$1001,,0)) -> rraven9@ed.gov | H11: =_xlfn.XLOOKUP(C11,customers!$A$1:$A$1001,customers!$G$1:$G$1001,,0) -> United States | I11: =INDEX(products!$A$1:$G$49,MATCH(orders!$D11,products!$A$1:$A$49,0),MATCH(orders!I$1,products!$A$1:$G$1,0)) -> Rob | J11: =INDEX(products!$A$1:$G$49,MATCH(orders!$D11,products!$A$1:$A$49,0),MATCH(orders!J$1,products!$A$1:$G$1,0)) -> M | K11: =INDEX(products!$A$1:$G$49,MATCH(orders!$D11,products!$A$1:$A$49,0),MATCH(orders!K$1,products!$A$1:$G$1,0)) -> 0.5 | L11: =INDEX(products!$A$1:$G$49,MATCH(orders!$D11,products!$A$1:$A$49,0),MATCH(orders!L$1,products!$A$1:$G$1,0)) -> 5.97 | M11: =L11*E11 -> 5.97 | N11: =IF(I11="Rob","Robusta",IF(I11="Exc","Excelsa",IF(I11="Ara","Arabica",IF(I11="Lib","Liberica","")))) -> Robusta | O11: =IF(J11="M","Medium",IF(J11="L","Light",IF(J11="D","Dark",""))) -> Medium | P11: =_xlfn.XLOOKUP(Orders[[#This Row],[Customer ID]],customers!$A$1:$A$1001,customers!$I$1:$I$1001,,0) -> No
A12: BKK-47233-845 | B12: 44263 | C12: 76239-90137-UQ | D12: A-D-1 | E12: 4 | F12: =_xlfn.XLOOKUP(orders!C12,customers!$A$1:$A$1001,customers!$B$1:$B$1001,,0) -> Ferrell Ferber | G12: =IF(_xlfn.XLOOKUP(orders!C12,customers!$A$1:$A$1001,customers!$C$1:$C$1001,,0)=0,"",_xlfn.XLOOKUP(orders!C12,customers!$A$1:$A$1001,customers!$C$1:$C$1001,,0)) -> fferbera@businesswire.com | H12: =_xlfn.XLOOKUP(C12,customers!$A$1:$A$1001,customers!$G$1:$G$1001,,0) -> United States | I12: =INDEX(products!$A$1:$G$49,MATCH(orders!$D12,products!$A$1:$A$49,0),MATCH(orders!I$1,products!$A$1:$G$1,0)) -> Ara | J12: =INDEX(products!$A$1:$G$49,MATCH(orders!$D12,products!$A$1:$A$49,0),MATCH(orders!J$1,products!$A$1:$G$1,0)) -> D | K12: =INDEX(products!$A$1:$G$49,MATCH(orders!$D12,products!$A$1:$A$49,0),MATCH(orders!K$1,products!$A$1:$G$1,0)) -> 1 | L12: =INDEX(products!$A$1:$G$49,MATCH(orders!$D12,products!$A$1:$A$49,0),MATCH(orders!L$1,products!$A$1:$G$1,0)) -> 9.95 | M12: =L12*E12 -> 39.8 | N12: =IF(I12="Rob","Robusta",IF(I12="Exc","Excelsa",IF(I12="Ara","Arabica",IF(I12="Lib","Liberica","")))) -> Arabica | O12: =IF(J12="M","Medium",IF(J12="L","Light",IF(J12="D","Dark",""))) -> Dark | P12: =_xlfn.XLOOKUP(Orders[[#This Row],[Customer ID]],customers!$A$1:$A$1001,customers!$I$1:$I$1001,,0) -> No
A13: VQR-01002-970 | B13: 44132 | C13: 49315-21985-BB | D13: E-L-2.5 | E13: 5 | F13: =_xlfn.XLOOKUP(orders!C13,customers!$A$1:$A$1001,customers!$B$1:$B$1001,,0) -> Duky Phizackerly | G13: =IF(_xlfn.XLOOKUP(orders!C13,customers!$A$1:$A$1001,customers!$C$1:$C$1001,,0)=0,"",_xlfn.XLOOKUP(orders!C13,customers!$A$1:$A$1001,customers!$C$1:$C$1001,,0)) -> dphizackerlyb@utexas.edu | H13: =_xlfn.XLOOKUP(C13,customers!$A$1:$A$1001,customers!$G$1:$G$1001,,0) -> United States | I13: =INDEX(products!$A$1:$G$49,MATCH(orders!$D13,products!$A$1:$A$49,0),MATCH(orders!I$1,products!$A$1:$G$1,0)) -> Exc | J13: =INDEX(products!$A$1:$G$49,MATCH(orders!$D13,products!$A$1:$A$49,0),MATCH(orders!J$1,products!$A$1:$G$1,0)) -> L | K13: =INDEX(products!$A$1:$G$49,MATCH(orders!$D13,products!$A$1:$A$49,0),MATCH(orders!K$1,products!$A$1:$G$1,0)) -> 2.5 | L13: =INDEX(products!$A$1:$G$49,MATCH(orders!$D13,products!$A$1:$A$49,0),MATCH(orders!L$1,products!$A$1:$G$1,0)) -> 34.155 | M13: =L13*E13 -> 170.775 | N13: =IF(I13="Rob","Robusta",IF(I13="Exc","Excelsa",IF(I13="Ara","Arabica",IF(I13="Lib","Liberica","")))) -> Excelsa | O13: =IF(J13="M","Medium",IF(J13="L","Light",IF(J13="D","Dark",""))) -> Light | P13: =_xlfn.XLOOKUP(Orders[[#This Row],[Customer ID]],customers!$A$1:$A$1001,customers!$I$1:$I$1001,,0) -> Yes
A14: SZW-48378-399 | B14: 44744 | C14: 34136-36674-OM | D14: R-M-1 | E14: 5 | F14: =_xlfn.XLOOKUP(orders!C14,customers!$A$1:$A$1001,customers!$B$1:$B$1001,,0) -> Rosaleen Scholar | G14: =IF(_xlfn.XLOOKUP(orders!C14,customers!$A$1:$A$1001,customers!$C$1:$C$1001,,0)=0,"",_xlfn.XLOOKUP(orders!C14,customers!$A$1:$A$1001,customers!$C$1:$C$1001,,0)) -> rscholarc@nyu.edu | H14: =_xlfn.XLOOKUP(C14,customers!$A$1:$A$1001,customers!$G$1:$G$1001,,0) -> United States | I14: =INDEX(products!$A$1:$G$49,MATCH(orders!$D14,products!$A$1:$A$49,0),MATCH(orders!I$1,products!$A$1:$G$1,0)) -> Rob | J14: =INDEX(products!$A$1:$G$49,MATCH(orders!$D14,products!$A$1:$A$49,0),MATCH(orders!J$1,products!$A$1:$G$1,0)) -> M | K14: =INDEX(products!$A$1:$G$49,MATCH(orders!$D14,products!$A$1:$A$49,0),MATCH(orders!K$1,products!$A$1:$G$1,0)) -> 1 | L14: =INDEX(products!$A$1:$G$49,MATCH(orders!$D14,products!$A$1:$A$49,0),MATCH(orders!L$1,products!$A$1:$G$1,0)) -> 9.95 | M14: =L14*E14 -> 49.75 | N14: =IF(I14="Rob","Robusta",IF(I14="Exc","Excelsa",IF(I14="Ara","Arabica",IF(I14="Lib","Liberica","")))) -> Robusta | O14: =IF(J14="M","Medium",IF(J14="L","Light",IF(J14="D","Dark",""))) -> Medium | P14: =_xlfn.XLOOKUP(Orders[[#This Row],[Customer ID]],customers!$A$1:$A$1001,customers!$I$1:$I$1001,,0) -> No
A15: ITA-87418-783 | B15: 43973 | C15: 39396-12890-PE | D15: R-D-2.5 | E15: 2 | F15: =_xlfn.XLOOKUP(orders!C15,customers!$A$1:$A$1001,customers!$B$1:$B$1001,,0) -> Terence Vanyutin | G15: =IF(_xlfn.XLOOKUP(orders!C15,customers!$A$1:$A$1001,customers!$C$1:$C$1001,,0)=0,"",_xlfn.XLOOKUP(orders!C15,customers!$A$1:$A$1001,customers!$C$1:$C$1001,,0)) -> tvanyutind@wix.com | H15: =_xlfn.XLOOKUP(C15,customers!$A$1:$A$1001,customers!$G$1:$G$1001,,0) -> United States | I15: =INDEX(products!$A$1:$G$49,MATCH(orders!$D15,products!$A$1:$A$49,0),MATCH(orders!I$1,products!$A$1:$G$1,0)) -> Rob | J15: =INDEX(products!$A$1:$G$49,MATCH(orders!$D15,products!$A$1:$A$49,0),MATCH(orders!J$1,products!$A$1:$G$1,0)) -> D | K15: =INDEX(products!$A$1:$G$49,MATCH(orders!$D15,products!$A$1:$A$49,0),MATCH(orders!K$1,products!$A$1:$G$1,0)) -> 2.5 | L15: =INDEX(products!$A$1:$G$49,MATCH(orders!$D15,products!$A$1:$A$49,0),MATCH(orders!L$1,products!$A$1:$G$1,0)) -> 20.585 | M15: =L15*E15 -> 41.17 | N15: =IF(I15="Rob","Robusta",IF(I15="Exc","Excelsa",IF(I15="Ara","Arabica",IF(I15="Lib","Liberica","")))) -> Robusta | O15: =IF(J15="M","Medium",IF(J15="L","Light",IF(J15="D","Dark",""))) -> Dark | P15: =_xlfn.XLOOKUP(Orders[[#This Row],[Customer ID]],customers!$A$1:$A$1001,customers!$I$1:$I$1001,,0) -> No
... A1001: IRV-20769-219 | B1001: 44119 | C1001: 77131-58092-GE | D1001: E-M-0.2 | E1001: 3 | F1001: =_xlfn.XLOOKUP(orders!C1001,customers!$A$1:$A$1001,customers!$B$1:$B$1001,,0) -> Vidovic Antonelli | G1001: =IF(_xlfn.XLOOKUP(orders!C1001,customers!$A$1:$A$1001,customers!$C$1:$C$1001,,0)=0,"",_xlfn.XLOOKUP(orders!C1001,customers!$A$1:$A$1001,customers!$C$1:$C$1001,,0)) | H1001: =_xlfn.XLOOKUP(C1001,customers!$A$1:$A$1001,customers!$G$1:$G$1001,,0) -> United Kingdom | I1001: =INDEX(products!$A$1:$G$49,MATCH(orders!$D1001,products!$A$1:$A$49,0),MATCH(orders!I$1,products!$A$1:$G$1,0)) -> Exc | J1001: =INDEX(products!$A$1:$G$49,MATCH(orders!$D1001,products!$A$1:$A$49,0),MATCH(orders!J$1,products!$A$1:$G$1,0)) -> M | K1001: =INDEX(products!$A$1:$G$49,MATCH(orders!$D1001,products!$A$1:$A$49,0),MATCH(orders!K$1,products!$A$1:$G$1,0)) -> 0.2 | L1001: =INDEX(products!$A$1:$G$49,MATCH(orders!$D1001,products!$A$1:$A$49,0),MATCH(orders!L$1,products!$A$1:$G$1,0)) -> 4.125 | M1001: =L1001*E1001 -> 12.375 | N1001: =IF(I1001="Rob","Robusta",IF(I1001="Exc","Excelsa",IF(I1001="Ara","Arabica",IF(I1001="Lib","Liberica","")))) -> Excelsa | O1001: =IF(J1001="M","Medium",IF(J1001="L","Light",IF(J1001="D","Dark",""))) -> Medium | P1001: =_xlfn.XLOOKUP(Orders[[#This Row],[Customer ID]],customers!$A$1:$A$1001,customers!$I$1:$I$1001,,0) -> Yes

Sheet customers
A1: Customer ID | B1: Customer Name | C1: Email | D1: Phone Number | E1: Address Line 1 | F1: City | G1: Country | H1: Postcode | I1: Loyalty Card
A2: 17670-51384-MA | B2: Aloisia Allner | C2: aallner0@lulu.com | D2: +1 (862) 817-0124 | E2: 57999 Pepper Wood Alley | F2: Paterson | G2: United States | H2: 7505 | I2: Yes
A3: 73342-18763-UW | B3: Piotr Bote | C3: pbote1@yelp.com | D3: +353 (913) 396-4653 | E3: 2112 Ridgeway Hill | F3: Crumlin | G3: Ireland | H3: D6W | I3: No
A4: 21125-22134-PX | B4: Jami Redholes | C4: jredholes2@tmall.com | D4: +1 (210) 986-6806 | E4: 5214 Bartillon Park | F4: San Antonio | G4: United States | H4: 78205 | I4: Yes
A5: 71253-00052-RN | B5: Dene Azema | C5: dazema3@facebook.com | D5: +1 (217) 418-0714 | E5: 27 Maywood Place | F5: Springfield | G5: United States | H5: 62711 | I5: Yes
A6: 23806-46781-OU | B6: Christoffer O' Shea | D6: +353 (698) 362-9201 | E6: 38980 Manitowish Junction | F6: Cill Airne | G6: Ireland | H6: N41 | I6: No
A7: 86561-91660-RB | B7: Beryle Cottier | D7: +1 (570) 289-7473 | E7: 2651 Stoughton Place | F7: Scranton | G7: United States | H7: 18505 | I7: No
A8: 65223-29612-CB | B8: Shaylynn Lobe | C8: slobe6@nifty.com | D8: +1 (937) 954-4541 | E8: 7005 Mariners Cove Place | F8: Dayton | G8: United States | H8: 45440 | I8: Yes
A9: 21134-81676-FR | B9: Melvin Wharfe | D9: +353 (507) 574-3034 | E9: 7 Straubel Road | F9: Kill | G9: Ireland | H9: P24 | I9: Yes
A10: 03396-68805-ZC | B10: Guthrey Petracci | C10: gpetracci8@livejournal.com | D10: +1 (310) 868-1842 | E10: 949 Paget Parkway | F10: Los Angeles | G10: United States | H10: 90045 | I10: No
A11: 61021-27840-ZN | B11: Rodger Raven | C11: rraven9@ed.gov | D11: +1 (213) 263-0288 | E11: 1 Reinke Avenue | F11: Los Angeles | G11: United States | H11: 90065 | I11: No
A12: 76239-90137-UQ | B12: Ferrell Ferber | C12: fferbera@businesswire.com | D12: +1 (408) 383-5302 | E12: 68 High Crossing Court | F12: San Jose | G12: United States | H12: 95160 | I12: No
A13: 49315-21985-BB | B13: Duky Phizackerly | C13: dphizackerlyb@utexas.edu | D13: +1 (408) 533-6012 | E13: 28643 Bluejay Crossing | F13: San Jose | G13: United States | H13: 95194 | I13: Yes
A14: 34136-36674-OM | B14: Rosaleen Scholar | C14: rscholarc@nyu.edu | D14: +1 (804) 420-0420 | E14: 80915 Montana Park | F14: Richmond | G14: United States | H14: 23285 | I14: No
A15: 39396-12890-PE | B15: Terence Vanyutin | C15: tvanyutind@wix.com | E15: 331 Bunting Hill | F15: Migrate | G15: United States | H15: 41905 | I15: No
A16: 95875-73336-RG | B16: Patrice Trobe | C16: ptrobee@wunderground.com | D16: +1 (314) 240-7896 | E16: 827 Declaration Plaza | F16: Saint Louis | G16: United States | H16: 63131 | I16: Yes
A17: 25473-43727-BY | B17: Llywellyn Oscroft | C17: loscroftf@ebay.co.uk | E17: 022 Roth Place | F17: Philadelphia | G17: United States | H17: 19172 | I17: No
A18: 99643-51048-IQ | B18: Minni Alabaster | C18: malabasterg@hexun.com | D18: +1 (971) 483-6255 | E18: 3 Charing Cross Trail | F18: Portland | G18: United States | H18: 97271 | I18: No
A19: 62173-15287-CU | B19: Rhianon Broxup | C19: rbroxuph@jimdo.com | D19: +1 (713) 663-1338 | E19: 83517 Thierer Court | F19: Houston | G19: United States | H19: 77240 | I19: No
A20: 57611-05522-ST | B20: Pall Redford | C20: predfordi@ow.ly | E20: 7337 Hayes Junction | F20: Caherconlish | G20: Ireland | H20: F45 | I20: Yes
A21: 76664-37050-DT | B21: Aurea Corradino | C21: acorradinoj@harvard.edu | D21: +1 (646) 202-5965 | E21: 698 Canary Terrace | F21: New York City | G21: United States | H21: 10060 | I21: Yes
A22: 84565-53984-SX | B22: Kendal Scardefield | D22: +353 (733) 405-3302 | E22: 3 Northridge Crossing | F22: Clondalkin | G22: Ireland | H22: D24 | I22: Yes
A23: 03090-88267-BQ | B23: Avrit Davidowsky | C23: adavidowskyl@netvibes.com | D23: +1 (616) 481-9962 | E23: 9 Warrior Junction | F23: Grand Rapids | G23: United States | H23: 49560 | I23: No
A24: 37651-47492-NC | B24: Annabel Antuk | C24: aantukm@kickstarter.com | D24: +1 (941) 740-6268 | E24: 77965 Lawn Park | F24: Punta Gorda | G24: United States | H24: 33982 | I24: Yes
A25: 95399-57205-HI | B25: Iorgo Kleinert | C25: ikleinertn@timesonline.co.uk | D25: +1 (360) 352-6598 | E25: 1 Morningstar Lane | F25: Vancouver | G25: United States | H25: 98682 | I25: Yes
A26: 24010-66714-HW | B26: Chrisy Blofeld | C26: cblofeldo@amazon.co.uk | D26: +1 (303) 936-3357 | E26: 013 Talisman Terrace | F26: Englewood | G26: United States | H26: 80150 | I26: No
A27: 07591-92789-UA | B27: Culley Farris | D27: +1 (941) 267-4822 | E27: 4 Mitchell Drive | F27: Punta Gorda | G27: United States | H27: 33982 | I27: Yes
A28: 49231-44455-IC | B28: Selene Shales | C28: sshalesq@umich.edu | D28: +1 (707) 881-5004 | E28: 74 Bultman Plaza | F28: Petaluma | G28: United States | H28: 94975 | I28: Yes
A29: 50124-88608-EO | B29: Vivie Danneil | C29: vdanneilr@mtv.com | D29: +353 (751) 346-0399 | E29: 5626 Darwin Avenue | F29: Tralee | G29: Ireland | H29: V92 | I29: No
A30: 00888-74814-UZ | B30: Theresita Newbury | C30: tnewburys@usda.gov | D30: +353 (803) 587-0026 | E30: 79526 Bultman Lane | F30: Clonskeagh | G30: Ireland | H30: D04 | I30: No
A31: 14158-30713-OB | B31: Mozelle Calcutt | C31: mcalcuttt@baidu.com | D31: +353 (928) 869-1762 | E31: 4389 Russell Way | F31: Rathwire | G31: Ireland | H31: Y25 | I31: Yes
A32: 51427-89175-QJ | B32: Adrian Swaine | D32: +1 (303) 486-9517 | E32: 95 Straubel Hill | F32: Aurora | G32: United States | H32: 80044 | I32: No
A33: 52082-49024-ON | B33: Ray Leivesley | C33: rleivesleyv@canalblog.com | D33: +1 (212) 535-7791 | E33: 91 Stephen Drive | F33: Jamaica | G33: United States | H33: 11407 | I33: No
A34: 04540-43685-DV | B34: Nelly Basezzi | C34: nbasezziw@webeden.co.uk | D34: +353 (125) 815-7345 | E34: 923 Mallard Junction | F34: Bailieborough | G34: Ireland | H34: C15 | I34: Yes
A35: 39123-12846-YJ | B35: Gallard Gatheral | C35: ggatheralx@123-reg.co.uk | E35: 40 Clemons Place | F35: Grand Forks | G35: United States | H35: 58207 | I35: No
A36: 44981-99666-XB | B36: Una Welberry | C36: uwelberryy@ebay.co.uk | D36: +44 (392) 503-8132 | E36: 40915 Schlimgen Park | F36: Upton | G36: United Kingdom | H36: DN21 | I36: Yes
A37: 24825-51803-CQ | B37: Faber Eilhart | C37: feilhartz@who.int | D37: +1 (304) 510-6095 | E37: 6966 Victoria Street | F37: Charleston | G37: United States | H37: 25362 | I37: No
A38: 77634-13918-GJ | B38: Zorina Ponting | C38: zponting10@altervista.org | D38: +1 (501) 172-1476 | E38: 7118 Holmberg Court | F38: Little Rock | G38: United States | H38: 72204 | I38: No
A39: 13694-25001-LX | B39: Silvio Strase | C39: sstrase11@booking.com | D39: +1 (303) 579-8015 | E39: 5 Forest Lane | F39: Denver | G39: United States | H39: 80291 | I39: No
A40: 08523-01791-TI | B40: Dorie de la Tremoille | C40: dde12@unesco.org | D40: +1 (612) 492-5160 | E40: 0817 Dennis Street | F40: Minneapolis | G40: United States | H40: 55458 | I40: No
...

Sheet products
A1: Product ID | B1: Coffee Type | C1: Roast Type | D1: Size | E1: Unit Price | F1: Price per 100g | G1: Profit
A2: A-L-0.2 | B2: Ara | C2: L | D2: 0.2 | E2: 3.885 | F2: 1.9425 | G2: 0.34965
A3: A-L-0.5 | B3: Ara | C3: L | D3: 0.5 | E3: 7.77 | F3: 1.554 | G3: 0.6993
A4: A-L-1 | B4: Ara | C4: L | D4: 1 | E4: 12.95 | F4: 1.295 | G4: 1.1655
A5: A-L-2.5 | B5: Ara | C5: L | D5: 2.5 | E5: 29.785 | F5: 1.1914 | G5: 2.68065
A6: A-M-0.2 | B6: Ara | C6: M | D6: 0.2 | E6: 3.375 | F6: 1.6875 | G6: 0.30375
A7: A-M-0.5 | B7: Ara | C7: M | D7: 0.5 | E7: 6.75 | F7: 1.35 | G7: 0.6075
A8: A-M-1 | B8: Ara | C8: M | D8: 1 | E8: 11.25 | F8: 1.125 | G8: 1.0125
A9: A-M-2.5 | B9: Ara | C9: M | D9: 2.5 | E9: 25.875 | F9: 1.035 | G9: 2.32875
A10: A-D-0.2 | B10: Ara | C10: D | D10: 0.2 | E10: 2.985 | F10: 1.4925 | G10: 0.26865
A11: A-D-0.5 | B11: Ara | C11: D | D11: 0.5 | E11: 5.97 | F11: 1.194 | G11: 0.5373
A12: A-D-1 | B12: Ara | C12: D | D12: 1 | E12: 9.95 | F12: 0.995 | G12: 0.8955
A13: A-D-2.5 | B13: Ara | C13: D | D13: 2.5 | E13: 22.885 | F13: 0.9154 | G13: 2.05965
... A49: E-D-2.5 | B49: Exc | C49: D | D49: 2.5 | E49: 27.945 | F49: 1.1178 | G49: 3.07395
